Workbook

Sheet Read me
A1: Joystick seed data
A2: Every mission in depth: the real problem, how roles combine to solve it, every stage, every squad's plan, and quests for every role. The app loads this file (db/seed/extract_workbook.py).
A4: How to read it
A5: • Start with Missions (the why), then Role map (who does what in each stage), then Quests (the actual work).
A6: • For you: the open quests each role would see first. This is what personalisation looks like in the demo.
A7: • IDs link the tabs. Stages, Squads and Quests point to a Mission ID. Quests point to a Squad ID and a Stage #.
A8: • Purple columns hold the detail. Blue cells are formulas, so don't type in them. Write comments in the yellow 'Your notes' column.
A9: • Facts lists every real-world number we rely on, with its source and how sure we are.
A11: At a glance
A12: Live missions | B12: =COUNTA(Missions!A2:A100)-COUNTA(Finished!A2:A100) -> 13
A13: Finished missions | B13: =COUNTA(Finished!A2:A100) -> 4
A14: Stages | B14: =COUNTA(Stages!A2:A500) -> 74
A15: Squads | B15: =COUNTA(Squads!A2:A200) -> 35
A16: Quests | B16: =COUNTA(Quests!A2:A2000) -> 234
A17: Open quests | B17: =COUNTIF(Quests!I2:I2000,"Open") -> 129
A18: People | B18: =COUNTA(People!A2:A200) -> 30
A19: Budget lines | B19: =COUNTA(Budget!A2:A1000) -> 190
A20: Risks | B20: =COUNTA(Risks!A2:A1000) -> 77
A21: Facts | B21: =COUNTA(Facts!A2:A1000) -> 95
A22: Open quests for Leaders | B22: =COUNTIFS(Quests!E2:E2000,"Leader",Quests!I2:I2000,"Open") -> 16
A23: Open quests for Planners | B23: =COUNTIFS(Quests!E2:E2000,"Planner",Quests!I2:I2000,"Open") -> 14
A24: Open quests for Experts | B24: =COUNTIFS(Quests!E2:E2000,"Expert",Quests!I2:I2000,"Open") -> 24
A25: Open quests for Makers | B25: =COUNTIFS(Quests!E2:E2000,"Maker",Quests!I2:I2000,"Open") -> 18
A26: Open quests for Checkers | B26: =COUNTIFS(Quests!E2:E2000,"Checker",Quests!I2:I2000,"Open") -> 15
A27: Open quests for Storytellers | B27: =COUNTIFS(Quests!E2:E2000,"Storyteller",Quests!I2:I2000,"Open") -> 13
A28: Open quests for Patrons | B28: =COUNTIFS(Quests!E2:E2000,"Patron",Quests!I2:I2000,"Open") -> 13
A29: Open quests for Users | B29: =COUNTIFS(Quests!E2:E2000,"User",Quests!I2:I2000,"Open") -> 16
A31: Copy rules
A32: • Mission titles: 6 words or fewer, a concrete promise.
A33: • Stage goals: something you can count.
A34: • Quests: verb first, under 10 words.
A35: • Modest, believable numbers. Never "millions".
A36: • No real organisations or people as players, partners or funders. Real laws, datasets and places are fine as sources.
A37: • India missions use ₹. Everything else uses $.
A39: Society ground rules
A40: • Never for or against a party or person. Public records only.
A41: • Every civic fact is checked by 2 checkers before it goes out.
A42: • No private people's details.
A43: • Every on-ground quest carries a safety note.
... A46: Leader · Planner · Expert · Maker · Checker · Storyteller · Patron · User (everyone is a User automatically)

Sheet Missions
A1: Mission ID | B1: Section | C1: Title | D1: One-line pitch | E1: State | F1: What a visitor learns | G1: Current stage | H1: Stages | I1: Prize | J1: Currency | K1: Players | L1: Squads | M1: Quests | N1: Open quests | O1: Roles with open quests (of 8) | P1: Budget planned | Q1: Creator | R1: Creator is… | S1: Where | T1: In the app today | U1: The problem today | V1: Who it helps | W1: Why it isn't solved yet | X1: What winning looks like | Y1: Rules | Z1: Hard parts | AA1: Partners needed | AB1: Data, laws & tools | AC1: Timeline | AD1: Your notes
A2: glio | B2: Health | C2: Make glioblastoma survivable | D2: Most people with this brain tumour die within 15 months, and that has barely changed in 20 years. Find a treatment that gives them years, fully open. | E2: Racing | F2: Squads race each other with different plans | G2: 3 | H2: =COUNTIF(Stages!$A$2:$A$1000,A2) -> 6 | I2: 250000 | J2: $ | K2: 640 | L2: =COUNTIF(Squads!$B$2:$B$1000,A2) -> 4 | M2: =COUNTIF(Quests!$B$2:$B$3000,A2) -> 16 | N2: =COUNTIFS(Quests!$B$2:$B$3000,A2,Quests!$I$2:$I$3000,"Open") -> 10 | O2: =SUMPRODUCT(--(COUNTIFS(Quests!$B$2:$B$3000,A2,Quests!$I$2:$I$3000,"Open",Quests!$E$2:$E$3000,{"Leader";"Planner";"Expert";"Maker";"Checker";"Storyteller";"Patron";"User"})>0)) -> 8 | P2: =SUMIF(Budget!$A$2:$A$3000,A2,Budget!$C$2:$C$3000) -> 250000 | Q2: Dr. Amara Osei | R2: Brain tumour doctor (fictional hospital) | S2: Global | T2: Existing · rename from 'Cure Glioblastoma' | U2: Glioblastoma is the most common aggressive brain cancer in adults. With today's standard treatment, median survival is about 15 months, and fewer than 1 in 10 patients live 5 years. Few new drugs have reached these patients in 20 years, partly because most drugs cannot get past the barrier that protects the brain. | V2: People with glioblastoma and their families: about 3 new cases per 100,000 people each year, roughly 12,000–14,000 a year in the US alone and many more worldwide. It also helps researchers, who get open, re-checked data. | W2: It is a small market with a high failure rate, so few companies invest. Tumours vary a lot between and within patients, and lab models often don't predict results in people. Data sits in many separate datasets, and closed patents stop groups from building on each other's work. | X2: • A new treatment reaches its first patients in a trial • 40 open datasets catalogued with licence and access notes • 50 targets ranked with public evidence for each • 10 candidates shortlisted, each with re-checked computer results and a written evidence summary • Top 10 tested by an independent partner lab, with all results published, including failures • A data package and pre-IND meeting request submitted through a trial sponsor | Y2: • Everything is open: data under CC BY 4.0, code under MIT. No patents that block others. • Only public or properly licensed data. No patient-identifiable data ever enters the game. • Players do no lab work. All lab testing is done by trained staff at accredited partner labs. • No medical advice to patients. The diet + drug squad shares research only, never personal plans. • Every result counts only after two Checkers have re-run or reviewed it, and negative results are published too. | Z2: • Reaching the brain: many drugs that work in a dish never get past the blood–brain barrier. • Tumours differ from patient to patient, so a target that matters in one dataset may not matter in another. • Computer predictions produce many false positives. Choosing 10 to pay lab time for is the costly decision. • Moving from open research to a trial needs a sponsor, money and regulators, and an open game controls none of these. | AA2: • An accredited contract lab with brain-tumour cell models (Riverside Bio, fictional) • A cloud provider giving discounted computing time (Nimbus Compute, fictional) • A hospital research group willing to sponsor a trial (Harbour Neuro-Oncology Unit, fictional) • A patient advocacy group (GBM Families Circle, fictional) • A regulatory consultancy (Clearpath Regulatory, fictional) | AB2: • TCGA-GBM via the NCI Genomic Data Commons portal • Chinese Glioma Genome Atlas (CGGA) public data • DepMap public portal • Open Targets Platform • ChEMBL and ZINC20 public libraries • ClinicalTrials.gov • FAIR data principles; CC BY 4.0 • US 21 CFR Part 312 (IND rules) and FDA guidance on formal meetings | AC2: About 3–4 years in total. The slowest steps are Stage 4 (lab booking and testing, 6–9 months) and Stage 5 (finding a sponsor and preparing the meeting request, 6–12 months).
A3: aid | B3: Health | C3: No one dies waiting for help | D3: In the minutes before an ambulance comes, the person next to you decides if you live. Help every bystander know what to do, in their own language. | E3: Recruiting | F3: There is a 15-minute quest you can do right now | G3: 1 | H3: =COUNTIF(Stages!$A$2:$A$1000,A3) -> 5 | I3: 20000 | J3: $ | K3: 38 | L3: =COUNTIF(Squads!$B$2:$B$1000,A3) -> 3 | M3: =COUNTIF(Quests!$B$2:$B$3000,A3) -> 18 | N3: =COUNTIFS(Quests!$B$2:$B$3000,A3,Quests!$I$2:$I$3000,"Open") -> 11 | O3: =SUMPRODUCT(--(COUNTIFS(Quests!$B$2:$B$3000,A3,Quests!$I$2:$I$3000,"Open",Quests!$E$2:$E$3000,{"Leader";"Planner";"Expert";"Maker";"Checker";"Storyteller";"Patron";"User"})>0)) -> 8 | P3: =SUMIF(Budget!$A$2:$A$3000,A3,Budget!$C$2:$C$3000) -> 20000 | Q3: Maria Santos | R3: ER nurse, Manila | S3: Global | T3: New | U3: Most good first-aid material exists in a handful of big languages. A parent in rural Mindanao or northern Nigeria who sees a child choke or get burned often has nothing in their own language to read, and wrong home remedies (butter on burns, toothpaste, induced vomiting) are still common. Injuries kill about 4.4 million people a year, and many deaths happen before any medic arrives. | V3: Families, teachers, drivers and community health volunteers who speak languages with little medical content: first wave includes Tagalog, Cebuano, Hausa, Yoruba, Amharic, Bengali, Odia, Nepali, Haitian Creole and Quechua, across Asia, Africa and Latin America. | W3: Translating medical text well costs money and nobody earns it back from small languages. Machine translation alone is risky for medical steps, and finding a native speaker who also understands first aid is slow. Large guideline bodies update in English first, so local versions go out of date. | X3: • Bystanders step in and help in 100 real emergencies • 20 guides agreed and signed off by at least 2 licensed nurses or doctors • All 20 guides live in 50 languages (1,000 guide-language pairs) • Every pair checked by a native speaker, and 1 in 10 back-translated to English with zero safety-changing errors • Free offline app under 30 MB plus printable A5 cards, released under CC BY 4.0 • Each guide shows the correct local emergency number for at least 50 countries | Y3: • Medical content only from current published resuscitation and first-aid guidelines; no home remedies, no product names. • A machine draft never ships unchecked: a native speaker fixes it, a Checker approves it. • Only adapt source text whose licence allows it; otherwise write fresh text. Everything we publish is CC BY 4.0. • Every guide starts with 'Call your local emergency number' and the right number for the reader's country. • No patient stories, photos or data of real people. | Z3: • Some words do not exist: 'airway' or 'recovery position' may need a short phrase or a picture, and choices must be consistent across all 20 guides. • Finding native speakers with medical sense for small languages like Quechua or Odia, and paying them fairly. • Guidelines change (CPR updates come every few years), so 1,000 pairs must be easy to update together. • Pictures must work across cultures and low literacy without words. • Low-end phones may lack fonts for some scripts (Ge'ez, Odia). | AA3: • A nurses' association that lends 2 reviewing nurses (Bayanihan Nurses Network, fictional) • A volunteer translator community for small languages (Many Tongues Collective, fictional) • A print shop that prints cards at cost for schools (Inkwell Print Co-op, fictional) • A small grant fund covering translator pay (Open Care Fund, fictional) | AB3: • IFRC International First Aid, Resuscitation and Education Guidelines 2020 • ILCOR Consensus on Science with Treatment Recommendations (CoSTR) summaries • WHO Basic Emergency Care course materials (as reference, licence checked) • Ethnologue / Glottolog for language codes and speaker counts • Unicode CLDR and Google Noto fonts for scripts • Weblate (open translation platform) with a shared glossary • Creative Commons BY 4.0 licence | AC3: About 9–12 months. The slowest step is Stage 3: finding and paying native-speaker checkers for the last 15 small languages.
A4: llm | B4: AI | C4: Every Indian can use AI in their language | D4: Most AI barely works in Odia, Bodo or Santali. Build a free model that does, and runs on one laptop. | E4: Merging | F4: Two plans can join forces | G4: 1 | H4: =COUNTIF(Stages!$A$2:$A$1000,A4) -> 5 | I4: 5000000 | J4: ₹ | K4: 310 | L4: =COUNTIF(Squads!$B$2:$B$1000,A4) -> 3 | M4: =COUNTIF(Quests!$B$2:$B$3000,A4) -> 16 | N4: =COUNTIFS(Quests!$B$2:$B$3000,A4,Quests!$I$2:$I$3000,"Open") -> 10 | O4: =SUMPRODUCT(--(COUNTIFS(Quests!$B$2:$B$3000,A4,Quests!$I$2:$I$3000,"Open",Quests!$E$2:$E$3000,{"Leader";"Planner";"Expert";"Maker";"Checker";"Storyteller";"Patron";"User"})>0)) -> 8 | P4: =SUMIF(Budget!$A$2:$A$3000,A4,Budget!$C$2:$C$3000) -> 5000000 | Q4: Vikram Rao | R4: AI researcher, Bengaluru | S4: India | T4: New · replaces the CAD mission | U4: India's Constitution lists 22 scheduled languages, but most AI models are trained mostly on English. Their tokenizers can cut a Tamil or Odia sentence into several times more pieces than the same English sentence. That makes them slower, costlier and worse at these languages. For languages like Santali, Bodo or Dogri there is very little clean, openly licensed text, and almost no tests that show whether a model actually understands them. | V4: Speakers of India's 22 scheduled languages, about 1.3 billion people. The first users are teachers, small government offices, local news desks and app makers in places like Odisha, Assam and Kashmir. They need an offline model that reads and writes their language and does not send data to a foreign cloud. | W4: Low-resource languages earn little money, so big labs rank them last and test them least. The text that does exist is scattered across old government PDFs, legacy non-Unicode fonts and sites with unclear licences, and cleaning it takes paid native speakers, not just scripts. Open benchmarks are thin for the smallest languages, so nobody can prove progress and nobody gets credit for it. | X4: • 10,000 people use it every week in their own language • 22 of 22 languages have at least 5 million clean, licence-checked words each, and the corpus totals 20 billion or more words • The tokenizer uses no more than 1.5× as many tokens per word in any Indic language as in English, measured on the FLORES-200 sentences • The model matches or beats open models of the same size (1–3B) in at least 15 of 22 languages on a held-out test, with all 22 scores published, including losses • The 4-bit model runs offline at 10 or more tokens per second on an 8 GB RAM laptop with no GPU • Weights, tokenizer, data card and licence log are released under an open licence; downloads are tracked for 90 days | Y4: • Use only text we have the right to use: public domain, government works covered by Copyright Act 1957 Sec. 52, or openly licensed (CC-BY, CC-BY-SA, CC0). Every source gets a line in the licence log, or it is dropped. • No personal data. Strip phone numbers, Aadhaar-like numbers, emails and names from private chats or forums, in line with the DPDP Act 2023. Do not scrape social media or private groups. • Test questions are written and frozen before training starts, and they are kept out of the training data. A leaked test means the result does not count. • Native speakers are paid at the same quest rate for every language. Rare-language Experts are not paid less because their text is 'small'. • Publish losses as well as wins: every language's score goes in the model card, including the ones where we lose. | Z4: • Data is very unequal. Hindi and Bengali have billions of words of web text. Bodo, Dogri, Santali (Ol Chiki script) and Kashmiri may have only a few million clean words, so the model can learn to ignore them. • Messy scripts: older Hindi, Odia and Tamil sites use legacy non-Unicode fonts that look right on screen but store garbage. There are also zero-width joiners, nukta variants, and Sindhi and Kashmiri text written in two scripts. • One tokenizer for about 12 scripts. If the vocabulary is too small, rare scripts break into single letters. If it is too large, a 1–2B model wastes its size on embeddings. • A small model trained on 20 billion words will read, write, translate and summarise well. It will reason weakly. The tests must measure what it can really do, and the team must not oversell it. • Fair tests: translated English benchmarks carry English culture and 'translationese'. Good tests need native-written questions for each of 22 languages, checked by a second speaker. | AA4: • A university linguistics department that lends native-speaker checkers for rare languages (Kalinga Language Lab, fictional) • An Indian GPU cloud that rents 64 GPUs by the hour at a research rate (Deccan Compute, fictional) • A publisher of regional-language textbooks and novels willing to licence back-catalogue text under CC-BY (Sahitya Setu Press, fictional) • A district education office that will pilot the laptop model in 10 schools (Koraput Learning Cell, fictional) | AB4: • Eighth Schedule of the Constitution of India (the list of 22 languages) • Copyright Act 1957 Sec. 52(1)(q) (reproducing Acts and court judgments is not infringement) • Digital Personal Data Protection Act 2023 • IndicCorp v2 and Sangraha open corpora (AI4Bharat) • Wikipedia dumps in the Indic languages; Common Crawl web snapshots • Samanantar and BPCC parallel corpora for translation pairs • FLORES-200 and IN22 test sets; IndicXTREME and IndicGenBench benchmarks • IndicLID and fastText for language identification; IndicNLP Library for script normalisation • SentencePiece (unigram/BPE tokenizer); MinHash-LSH for near-duplicate removal • EleutherAI lm-evaluation-harness for repeatable scoring • llama.cpp and the GGUF format for 4-bit laptop builds • Bhashini (Government of India language platform) for checking open datasets | AC4: About 7–9 months. Data takes 3–4 months, training 1–2 months, testing 6–8 weeks and shipping about 4 weeks. The slowest step is finding and cleaning enough licensed text for the 6–8 smallest languages, because that needs paid native speakers, not more GPUs.
A5: harness | B5: AI | C5: Agents you can trust with real work | D5: Nobody lets an agent touch real money or code unwatched. Build the open engine that makes Joystick's agents safe to trust. | E5: Racing | F5: You can help build the game itself | G5: 2 | H5: =COUNTIF(Stages!$A$2:$A$1000,A5) -> 4 | I5: 60000 | J5: $ | K5: 190 | L5: =COUNTIF(Squads!$B$2:$B$1000,A5) -> 2 | M5: =COUNTIF(Quests!$B$2:$B$3000,A5) -> 16 | N5: =COUNTIFS(Quests!$B$2:$B$3000,A5,Quests!$I$2:$I$3000,"Open") -> 11 | O5: =SUMPRODUCT(--(COUNTIFS(Quests!$B$2:$B$3000,A5,Quests!$I$2:$I$3000,"Open",Quests!$E$2:$E$3000,{"Leader";"Planner";"Expert";"Maker";"Checker";"Storyteller";"Patron";"User"})>0)) -> 8 | P5: =SUMIF(Budget!$A$2:$A$3000,A5,Budget!$C$2:$C$3000) -> 60000 | Q5: Kit Bashford | R5: Agent engineer, 12 years | S5: Global | T5: New · replaces the CAD mission | U5: An agent that can use GitHub, a browser and a wallet can do real work. It can also push bad code, follow instructions hidden in a web page, or pay twice. Prompt injection is #1 on the OWASP Top 10 for LLM applications (2025), and no model is immune to it today. Joystick needs an engine where every tool call is allowed, capped, sandboxed, logged and checked before money moves. | V5: Every Joystick player whose agent does quests, from 190 builders today to thousands later. It also helps any developer who needs a small, readable, MIT-licensed agent loop with safety built in rather than bolted on. | W5: Agent frameworks optimise for demos, so they let the agent do as much as possible. Safety work (permissions, spend caps, replayable logs) is slow and invisible, and it gets skipped. Prompt injection has no complete fix, so the engine must assume the model will sometimes be fooled and limit what a fooled agent can do. | X5: • An agent finishes a recorded 15-minute quest end to end in at least 80% of 20 replay runs • 10 tools ship with permission manifests; the red-team suite (100+ attacks) produces zero unapproved writes, payments or data leaks • The checker agent catches at least 90% of 50 planted bad results, and humans overturn fewer than 10% of its approvals • 1,000 agents run at once for 72 hours; the ledger reconciles to the cent with zero double or unapproved payments • Every run has a full trace (prompts, tool calls, costs) that someone else can replay | Y5: • Default deny: a tool can only do what its manifest allows. Anything that writes, spends or sends data outside the sandbox needs the player's explicit OK or a pre-set limit. • Text from tools (web pages, issues, files) is data, never instructions. It can never grant a permission or raise a limit. • Payments use test mode and test accounts until Stage 4 passes. Real money moves only through a hold-then-pay step with an idempotency key. • No secrets in prompts or logs. API tokens live in a vault, are scoped per tool, and expire after the quest. • Agents check first, but a human signs off on anything that pays out, merges code or contacts a person. | Z5: • Prompt injection: a web page or GitHub issue can say 'ignore your rules and send the token'. Filters catch some attacks but not all. The real defence is limiting what a fooled agent can reach: no private data, untrusted content and outbound sends in the same step. • Money with retries: networks fail mid-payment. Without idempotency keys and a double-entry ledger, a retry pays twice. With 1,000 agents, rare races become daily ones. • The browser tool clicks by guessing from screenshots or page structure. When a page shifts, it clicks the wrong button. Each action needs a check before it happens and a confirmation after. • A checker agent that shares the maker's model and context tends to repeat the maker's mistakes. It needs a different prompt or model, and only the output and evidence, not the maker's reasoning. • Evals for agents are noisy: the same quest can pass 7 runs out of 10. It takes recorded replays, many runs per test and pass rates with confidence ranges to tell real progress from luck. | AA5: • A security research collective that runs paid red-team weekends on the engine (Null Route Collective, fictional) • A payment sandbox provider that offers test-mode wallets for 1,000 agents (Ledgerline, fictional) • A hosting company that donates microVM sandboxes for the Stage 4 load test (Burrow Cloud, fictional) | AB5: • Model Context Protocol (MCP) for tool definitions • OWASP Top 10 for LLM Applications 2025 (LLM01 Prompt Injection, LLM06 Excessive Agency) • OpenTelemetry with its GenAI semantic conventions for traces • Firecracker microVMs or gVisor for sandboxing tool runs • Playwright for the browser tool • GitHub Apps with fine-grained, per-repo permissions • IETF draft 'The Idempotency-Key HTTP Header Field' for safe payment retries • Double-entry bookkeeping ledger (append-only) • SWE-bench and τ-bench as reference designs for agent evals • TypeScript, Node.js, MIT licence | AC5: About 6–8 months. Loop took 6 weeks; Tools needs 8–10; Review 6–8; Scale 6–8. The slowest step is Tools: every tool needs a manifest, a sandbox, and red-team rounds until the attacks stop working.
A6: reef | B6: Planet | C6: Catch dying reefs in time to save them | D6: Reefs bleach in weeks, and most are never checked. Warn the people who look after them early enough to act. | E6: Stuck | F6: Blockers, and how you can help | G6: 2 | H6: =COUNTIF(Stages!$A$2:$A$1000,A6) -> 4 | I6: 85000 | J6: $ | K6: 95 | L6: =COUNTIF(Squads!$B$2:$B$1000,A6) -> 2 | M6: =COUNTIF(Quests!$B$2:$B$3000,A6) -> 15 | N6: =COUNTIFS(Quests!$B$2:$B$3000,A6,Quests!$I$2:$I$3000,"Open") -> 9 | O6: =SUMPRODUCT(--(COUNTIFS(Quests!$B$2:$B$3000,A6,Quests!$I$2:$I$3000,"Open",Quests!$E$2:$E$3000,{"Leader";"Planner";"Expert";"Maker";"Checker";"Storyteller";"Patron";"User"})>0)) -> 8 | P6: =SUMIF(Budget!$A$2:$A$3000,A6,Budget!$C$2:$C$3000) -> 85000 | Q6: Blue Carbon Lab | R6: Marine charity (fictional) | S6: Global | T6: Existing | U6: Reefs are bleaching faster than people can survey them. NOAA confirmed the fourth global bleaching event in 2024, and an estimated 14% of the world's coral was lost between 2009 and 2018. Sea-temperature satellites warn when water is too hot, but they cannot say whether a particular reef actually bleached or died. Divers can, but they reach only a few sites a year. | V6: Coastal fishers, reef managers and marine-park rangers. The first focus is the central Philippines (Cebu, Bohol) and Fiji, where reefs feed and protect millions of people. A free map shows them where to look first after a heatwave. | W6: Satellite images that see coral detail cost money, and free 10 m images blur coral, algae and sand together. Turning images into health maps needs thousands of ground checks by divers, timed close to a cloud-free satellite pass, and dive trips are expensive. Funders pay for one-off surveys, not for the slow, boring work of keeping a map up to date every week. | X6: • 50 reef keepers get a weekly warning they trust • 200 survey sites scored on site with photo-quadrats, each within 30 days of a cloud-free satellite image • Model reaches 80% or better balanced accuracy on 3 classes (healthy / bleached / dead or algae) on 40 held-back sites • Public map updates its heat-stress layer weekly and its reef-cover layer within 7 days of each usable image, for at least 6 months • Every agent-made map tile shown in public has been spot-checked by a human • At least 3 reef managers (rangers, park staff) say in writing that they used the map to choose where to survey | Y6: • Dive safety comes first. Certified divers only, always with a buddy, no deeper than 18 m, with a local licensed operator and dive insurance. No dive in bad weather. • Touch nothing. Surveys are photo-only, with no sampling, no anchoring on coral, and fins kept off the reef. • Get permits and pay fees for marine protected areas, and ask local communities before surveying their fishing grounds. • No agent-only results count until a human Checker has reviewed them. • Open data: survey photos and scores are released under CC-BY. Exact locations of fragile or poached sites can be blurred on request from local managers. | Z6: • Depth and water: optical satellites see the seabed only in clear, shallow water. Past about 10–15 m, or in murky water, the signal is mostly the water itself. • Pixel size: a 10 m Sentinel-2 pixel mixes coral, sand, rubble and algae. Bleaching shows up as brightening, and sand does too. • Timing: bleached coral either recovers or dies within weeks. A dive score is only useful if it is close in time to a cloud-free image. The tropics are cloudy in the wet season. • Ground truth is expensive: each boat day costs a few hundred dollars and covers 2–3 sites. Without cheaper methods (snorkel surveys on reef flats), Stage 2 stalls, as it has now. • Agent-only mapping looks productive but can be confidently wrong. Without human checks, errors spread across the whole map. | AA6: • A small dive operator in Moalboal, Cebu that offers boat days at cost (Bantay Dagat Divers, fictional) • A dive shop in Fiji willing to train 2 local divers in the survey method (Lomaiviti Reef Divers, fictional) • A marine-park ranger team who will use the map and give feedback (Bohol Sanctuary Wardens, fictional) • A university remote-sensing lab that lends a GPU and reviews the model (Visayas Ocean Lab, fictional) | AB6: • Sentinel-2 imagery (10 m, about 5-day revisit) via the Copernicus Data Space • Landsat 8/9 imagery for the longer history • Allen Coral Atlas reef extent and habitat maps • NOAA Coral Reef Watch sea-surface temperature and Degree Heating Weeks • CoralNet for annotating benthic photo-quadrats • CoralWatch Coral Health Chart for colour scoring • Reef Check / line-intercept transect methods • QGIS and open Python tools (rasterio, scikit-learn) • Local government marine protected area permits (Philippines Fisheries Code, RA 8550 as amended) | AC6: About 12–15 months. The pilot took 2 months. Ground truth needs 4–6 more months and is the slowest step because of boat money, weather and the dive season. The model takes 3 months, and the public map about 2 months to build, then runs on.
A7: lead | B7: Planet | C7: No child in Dayton drinks lead | D7: Thousands of Dayton homes may still get water through lead pipes. Find them and get them replaced, homes with kids first. | E7: Proposed | F7: Players decide what gets started | G7: 0 | H7: =COUNTIF(Stages!$A$2:$A$1000,A7) -> 5 | I7: 30000 | J7: $ | K7: 0 | L7: =COUNTIF(Squads!$B$2:$B$1000,A7) -> 2 | M7: =COUNTIF(Quests!$B$2:$B$3000,A7) -> 16 | N7: =COUNTIFS(Quests!$B$2:$B$3000,A7,Quests!$I$2:$I$3000,"Open") -> 10 | O7: =SUMPRODUCT(--(COUNTIFS(Quests!$B$2:$B$3000,A7,Quests!$I$2:$I$3000,"Open",Quests!$E$2:$E$3000,{"Leader";"Planner";"Expert";"Maker";"Checker";"Storyteller";"Patron";"User"})>0)) -> 8 | P7: =SUMIF(Budget!$A$2:$A$3000,A7,Budget!$C$2:$C$3000) -> 30000 | Q7: Bill Turner | R7: Retired civil engineer, Ohio | S7: Dayton, USA | T7: New | U7: Lead service lines carry water from the street main into older homes. Lead can leach into tap water, and there is no known safe blood lead level for children. The US EPA estimates about 9 million lead service lines are still in use nationwide. Like other cities, Dayton had to publish an inventory in 2024, but cities across the US list many lines as 'status unknown', and a line nobody has confirmed cannot be put on a replacement schedule. | V7: Households in Dayton's older neighbourhoods, mainly homes built before the 1950s–60s, where lead lines are most likely. Families with young children and renters, who often don't know what pipe they have, benefit first. It also helps the city's water department, which needs confirmed lines to plan and fund replacement. | W7: Confirming each line means someone has to look at the pipe in a basement, and a city crew visit to every home is slow and costly. The pipe is often split in ownership (the city owns one side, the homeowner the other), so nobody owns the whole problem. Residents can identify their own pipe in 5 minutes with a magnet and a coin, but there is no simple, trusted way to collect what they find. | X7: • 500 lead lines replaced, homes with children first • Every address in the public inventory is matched to a block on the map, and 'unknown' lines are counted by block • 1,000 resident photos of 'unknown' lines are checked, with each one called lead, galvanised, copper or plastic • Photo calls match a licensed plumber's check on at least 90% of 40 randomly picked homes • A public block-level map is live and is updated monthly for 12 months • The city publishes a dated plan to replace at least 500 confirmed lead lines, with the confirmed lines first | Y7: • Strictly non-partisan: no candidates, parties or campaigns. Every ask goes to the city through public channels, such as records requests and public comment. • Public records and willing residents only. Photos come only from your own home, or a home whose owner says yes in writing. No door-to-door collection. • Privacy: the map shows status by block. A house appears only if its owner opts in. Photo metadata (GPS, faces) is stripped. • Never cut, unscrew or bend a pipe. A light scratch with a coin and a magnet test is the limit. Wash your hands afterwards. • No health advice beyond public guidance. Point people to the city's and EPA's lead guidance and filter information. | Z7: • Split ownership: the city side and the home side can be different materials, and a basement photo only shows the home side. • Galvanised pipe that was once downstream of lead also counts for replacement under the 2024 rules. Residents can't see the history. • Photos fool people. Painted pipes, wrapped pipes and dark basements make a magnet-and-scratch test the only reliable home check. • Turnout is uneven. Homeowners in better-off streets reply more, but the unknown lines are often in rentals. The map must show where data is missing, not just where lead is. • The city already has a legal deadline. The mission must help it, not compete with it, or the data will be ignored. | AA7: • A neighbourhood association in an older west-side area that hosts sign-up nights (Westwood Porch Network, fictional) • A licensed plumbing co-op that checks 40 random homes to confirm photo accuracy (Gem City Plumbers Co-op, fictional) • A local library branch that lends magnets and hosts help desks (Riverbend Library Friends, fictional) | AB7: • EPA Lead and Copper Rule Revisions (2021): service line inventories due 16 Oct 2024 • EPA Lead and Copper Rule Improvements (2024): replacement within about 10 years • City of Dayton public lead service line inventory • Ohio Public Records Act, ORC 149.43 • Ohio Revised Code 6109.21 (lead line mapping by water systems, from HB 512, 2016) • EPA 'Protect Your Tap' pipe identification guide • Montgomery County Auditor parcel data (year built) • US Census American Community Survey (housing age, renters) • OpenStreetMap and QGIS for the block map | AC7: About 9–12 months. Records take 1–2 months (public records replies can be slow), photos 4–5 months, the map 1–2 months, then 2–3 months to get a dated city plan. The slowest step is getting enough photos from renters and the oldest blocks.
A8: tutor | B8: Learning | C8: Every child can do basic maths | D8: Many children finish primary school without basic maths. Get them there, even where there's no internet. | E8: Final stage | F8: What a finish looks like | G8: 4 | H8: =COUNTIF(Stages!$A$2:$A$1000,A8) -> 4 | I8: 120000 | J8: $ | K8: 180 | L8: =COUNTIF(Squads!$B$2:$B$1000,A8) -> 2 | M8: =COUNTIF(Quests!$B$2:$B$3000,A8) -> 16 | N8: =COUNTIFS(Quests!$B$2:$B$3000,A8,Quests!$I$2:$I$3000,"Open") -> 9 | O8: =SUMPRODUCT(--(COUNTIFS(Quests!$B$2:$B$3000,A8,Quests!$I$2:$I$3000,"Open",Quests!$E$2:$E$3000,{"Leader";"Planner";"Expert";"Maker";"Checker";"Storyteller";"Patron";"User"})>0)) -> 8 | P8: =SUMIF(Budget!$A$2:$A$3000,A8,Budget!$C$2:$C$3000) -> 120000 | Q8: Chioma Okafor | R8: Head teacher, Lagos | S8: 10 countries | T8: Existing · rename from 'Free AI tutor for 1M kids' | U8: Many children finish primary school without being able to do basic maths. UNESCO estimates about 6 in 10 children and teenagers worldwide were not reaching minimum skill in reading and maths. Classes of 40–60 children leave teachers no time for one-to-one help, and most tutoring apps need fast internet and expensive phones. | V8: Children aged 8–11 (roughly Primary 3–5) in low-cost schools in Nigeria, Ghana, Kenya, Tanzania, Uganda, Rwanda, Ethiopia, India, Bangladesh and the Philippines. The pilot reached 500 children in 25 classes. One shared phone serves a small group in class. | W8: Children and schools in these places cannot pay, so companies build for richer markets with good internet. Every country has its own curriculum and language, so one app does not fit all. Few groups run fair tests, so nobody knows which tools really help. | X8: • Works fully offline on a phone costing about $50 (1–2 GB RAM, Android Go) and fits under 150 MB • Covers the national maths curriculum for 3 grade levels in all 10 countries • 500 pilot children use it at least 3 times a week for 4 weeks • In all 10 countries, pilot classes' average score rises at least 10% from their start score and beats the comparison class • Code, content and test items released openly (MIT for code, CC BY 4.0 for content) | Y8: • Child safety first: an adult school staff member is always present, and no player is ever alone with a child. • Written consent from a parent or guardian, and agreement from the head teacher, before any child uses the app or takes a test. • No names, photos or voice of children are stored. Each child gets a code, and the key to the codes stays at the school. • Follow each country's data law (for example the Kenya Data Protection Act 2019, Nigeria Data Protection Act 2023, India DPDP Act 2023). • Report every country's result honestly, including ones that miss the target. | Z8: • Running a helpful tutor on 1–2 GB of RAM with no internet means a tiny model or rule-based hints, not a big chatbot. • 10 curricula and 10 languages: maths words such as 'carry' or 'fraction' differ even between nearby regions. • Fair testing: 4 weeks is short, samples are small (about 50 per country), and teachers may 'teach to the test'. • Phones get shared, lost or run flat. Charging in schools without power is a real limit. • Keeping schools engaged after the pilot ends. | AA8: • A network of low-cost schools in 10 countries (Bright Bench Schools Network, fictional) • A refurbished-phone supplier offering $50 handsets (SecondLife Devices, fictional) • A university education department that reviews the test design (Lakeside University Education Lab, fictional) • A small education fund (Open Slate Fund, fictional) | AB8: • Early Grade Mathematics Assessment (EGMA) open toolkit, used to build the 20-minute test • National curricula: Nigeria NERDC Basic Education Curriculum, Kenya CBC (KICD), India NCERT, Philippines DepEd K-12 MELCs • UNESCO UIS SDG 4.1.1 learning data • Android Go and LiteRT (TensorFlow Lite) for on-device models • Kenya Data Protection Act 2019; Nigeria Data Protection Act 2023; India DPDP Act 2023 • ODK / Kobo-style offline forms for collecting test scores | AC8: About 12 months in total. The slowest step was Stage 3: school permissions and parent consent took 2–3 months in some countries. Stage 4 now waits on the end-of-term Kenya test.
A9: benefits | B9: Society | C9: Get families the benefits they're owed | D9: Help poor families in UP claim the pensions, scholarships and ration they already have a right to. | E9: Racing | F9: Society missions work like science ones | G9: 2 | H9: =COUNTIF(Stages!$A$2:$A$1000,A9) -> 4 | I9: 1500000 | J9: ₹ | K9: 260 | L9: =COUNTIF(Squads!$B$2:$B$1000,A9) -> 3 | M9: =COUNTIF(Quests!$B$2:$B$3000,A9) -> 16 | N9: =COUNTIFS(Quests!$B$2:$B$3000,A9,Quests!$I$2:$I$3000,"Open") -> 9 | O9: =SUMPRODUCT(--(COUNTIFS(Quests!$B$2:$B$3000,A9,Quests!$I$2:$I$3000,"Open",Quests!$E$2:$E$3000,{"Leader";"Planner";"Expert";"Maker";"Checker";"Storyteller";"Patron";"User"})>0)) -> 8 | P9: =SUMIF(Budget!$A$2:$A$3000,A9,Budget!$C$2:$C$3000) -> 1500000 | Q9: Meera Joshi | R9: NGO coordinator, Lucknow | S9: Sitapur & Banda, Uttar Pradesh | T9: New | U9: Families in Uttar Pradesh can claim old-age and widow pensions, free ration under the National Food Security Act, PM-KISAN and student scholarships. Many who qualify never get them. The forms are online, each one needs 2–4 certificates first (income, caste, domicile), and the money only arrives if the bank account is linked to Aadhaar for Direct Benefit Transfer (DBT). A widow aged 40–79 below the poverty line can get a monthly pension, but first she must know it exists, get an income certificate from the tehsil and apply on the state pension portal. | V9: Poor rural families in two UP districts, Sitapur and Banda: widows, elderly people, small farmers and students from SC, ST, OBC and minority families. The helper answers anyone in UP. The on-ground pilot aims at 1,000 families. | W9: Each scheme belongs to a different department with its own portal, rules and documents, so nobody owns the whole picture for one family. Middlemen charge fees to fill free forms, and families stop trusting help. When payments fail because the Aadhaar seeding or the name spelling doesn't match, nobody tells the family why. | X9: • 50 scheme cards checked against the official government orders, each with the benefit, who qualifies, the documents needed and where to apply • The helper answers correctly in 6 languages: at least 90% right on a 30-question test set per language, with zero answers that ask for an Aadhaar number, OTP or bank PIN • 1,000 families in Sitapur and Banda submit complete applications, each with an official registration number • 750 families show a first payment credited in their bank account (passbook or official portal status) • No family pays the mission or a volunteer anything | Y9: • Never collect, photograph or store Aadhaar numbers, OTPs, bank PINs or document copies. Families keep their own papers (Aadhaar Act 2016 Sec. 29, DPDP Act 2023). • Help is always free. Families pay only the official fee at a Common Service Centre (CSC), against a printed receipt. • Apply only through official portals, CSCs or block offices. Never through an agent who promises to 'get it sanctioned'. • Non-partisan: no party names, symbols or leaders' photos on any material, and never tell families a benefit comes from a party. • Any family story or photo needs that family's spoken consent in their own language, and it can be withdrawn at any time. | Z9: • Documents come before schemes. A pension application stalls for weeks until the tehsil issues an income certificate, and caste certificates can take longer. • DBT failures are invisible. A payment 'sent' on the portal bounces if the account isn't Aadhaar-seeded on the NPCI mapper, is dormant, or the name spelling differs between Aadhaar and the bank. • Rules differ by scheme and change by government order: age bands, income limits and whether a widow can draw both the state and central pension. The 50 cards go stale. • Many applicants can't read well. The helper has to work with voice notes in Awadhi or Bundeli, not just typed Hindi. • Sanction sits with officials (BDO, SDM, District Social Welfare Officer). We can help families apply and follow up, but we can't speed up approval. | AA9: • A Lucknow network of form-help NGOs with field staff in Sitapur and Banda (Awadh Seva Sangh, fictional) • A WhatsApp Business solution provider to host the helper number (BolChal Tech, fictional) • Village-level CSC operators in the pilot blocks who agree to post their fees (Sidhauli Digital Seva Kendra, fictional) • A rural bank branch that runs Aadhaar-seeding camps (Gramin Setu Bank, fictional) | AB9: • myScheme portal (myscheme.gov.in) for scheme rules • UP Social Security Pension portal (sspy-up.gov.in) for old-age, widow and disability pensions • UP Scholarship portal (scholarship.up.gov.in) • e-District UP (edistrict.up.gov.in) for income, caste and domicile certificates • National Food Security Act 2013 and UP Food & Civil Supplies portal (fcs.up.gov.in) for ration card status • PM-KISAN beneficiary status page (pmkisan.gov.in) • NSAP guidelines (Indira Gandhi National Widow and Old Age Pension Schemes) • Bhashini (Govt. of India language tools) for first-draft translation, always reviewed by a native speaker • IGRS Jansunwai portal / CM Helpline 1076 and RTI Act 2005 Sec. 6 for stuck applications | AC9: About 10–12 months in total. The slowest step is Stage 4: after a family applies, verification by the block or tehsil and sanction by the district officer often take 1–3 months, and pensions are paid in quarterly instalments.
A10: candidate | B10: Society | C10: Every Pune voter chooses with facts | D10: Candidates' sworn facts are public but buried in long PDFs. Put them in front of voters in Pune district before they vote. | E10: Countdown | F10: Some missions race a deadline (12 days to voting day) | G10: 2 | H10: =COUNTIF(Stages!$A$2:$A$1000,A10) -> 4 | I10: 500000 | J10: ₹ | K10: 120 | L10: =COUNTIF(Squads!$B$2:$B$1000,A10) -> 2 | M10: =COUNTIF(Quests!$B$2:$B$3000,A10) -> 17 | N10: =COUNTIFS(Quests!$B$2:$B$3000,A10,Quests!$I$2:$I$3000,"Open") -> 11 | O10: =SUMPRODUCT(--(COUNTIFS(Quests!$B$2:$B$3000,A10,Quests!$I$2:$I$3000,"Open",Quests!$E$2:$E$3000,{"Leader";"Planner";"Expert";"Maker";"Checker";"Storyteller";"Patron";"User"})>0)) -> 8 | P10: =SUMIF(Budget!$A$2:$A$3000,A10,Budget!$C$2:$C$3000) -> 500000 | Q10: Arjun Mehta | R10: Journalist, Mumbai | S10: Pune district, 21 Assembly seats | T10: New | U10: Every Assembly candidate must file a sworn affidavit (Form 26) listing criminal cases, assets, debts and education. The Election Commission puts them online, but each one is a 15–40 page scanned PDF in dense legal English or Marathi, and few voters ever open one. This election, Pune district's 21 seats have about 310 candidates and 12 days to go. | V10: Voters in Pune district's 21 Assembly constituencies (more than 80 lakh registered voters), especially first-time voters and people who follow the news in Marathi. | W10: Affidavits are scanned images, not data, so every number has to be read and typed by a person. The window between the final candidate list and polling day is only about two weeks. Media cover the big races and skip most independents. Any slip can bring a defamation notice or a charge of bias, so few groups want the risk. | X10: • 310 profiles on one identical template, in Marathi and English • Every fact carries the affidavit page number it came from • Every profile passes 2 independent checks, with zero open factual disputes at publication • 1,00,000 unique visits to profile pages before the 48-hour silence period begins • Equal-treatment audit passed: same fields, same length limit, same order (ballot order from Form 7A) for every candidate | Y10: • Public records only: Form 26 affidavits and the Returning Officer's list of contesting candidates (Form 7A). No social media, news reports or rumours. • Strictly non-partisan: no party logos or colours, no adjectives, no ranking, no 'best' or 'worst'. A pending case is written as 'case pending, not convicted'. • Never publish addresses, PAN, phone numbers, bank details or family members' names, even when the affidavit shows them. • All sharing stops when the 48-hour silence period begins (RP Act 1951 Sec. 126). No paid promotion at any time. • Anyone working for a party or campaign declares it and does not write or check profiles in that constituency. | Z10: • Scans are poor: mixed Marathi and English, handwriting, stamps across text. OCR gets many numbers wrong, so every figure must be read by a person. • Assets are split across self, spouse, HUF and dependents, in movable and immovable tables. Adding them up without double counting is easy to get wrong. • Criminal cases are listed by section number, under the old IPC or the new BNS (in force since July 2024). Turning a section into plain words without implying guilt takes care. • The list keeps changing: withdrawals, rejected nominations and candidates with the same name all arrive days before polling. • Supporters of every side will call the profiles biased, so the process has to be provably the same for everyone. | AA10: • A Pune law college's legal-aid clinic to review the template and risky wording (Deccan Law Clinic, fictional) • A desk of retired Marathi sub-editors for translation (Shabda Desk, fictional) • Housing society federations and college volunteer units to share links (Kothrud Residents' Forum, fictional) • An election-law adviser on call for legal notices (Adv. S. Patwardhan, fictional) | AB10: • Form 26 affidavits on the ECI affidavit portal (affidavit.eci.gov.in) • Conduct of Election Rules 1961, Rule 4A and Form 26 • Form 7A list of contesting candidates from each Returning Officer, via the Chief Electoral Officer, Maharashtra site • Representation of the People Act 1951: Sec. 30 (timeline), Sec. 125A (false affidavit), Sec. 126 (48-hour silence) • ECI Model Code of Conduct and its social media guidance • IPC 1860 and Bharatiya Nyaya Sanhita 2023 section lists, for the plain-language case glossary • Tesseract OCR with the Marathi (mar) model, for first-pass extraction only | AC10: About 4 weeks from the close of nominations to polling day. That's roughly 4 days to collect, 8 days to write profiles, 4 days for second checks and corrections, and 6 days to share before the silence period. The slowest step is the second independent check, because every number has to be traced back to a page.
A11: pothole | B11: Society | C11: No rider hurt by a Bengaluru pothole | D11: Potholes throw Bengaluru's riders off their bikes every week. Get the worst ones fixed fast, and keep them fixed. | E11: Just started | F11: Lots of quick quests on your way home | G11: 1 | H11: =COUNTIF(Stages!$A$2:$A$1000,A11) -> 5 | I11: 800000 | J11: ₹ | K11: 340 | L11: =COUNTIF(Squads!$B$2:$B$1000,A11) -> 2 | M11: =COUNTIF(Quests!$B$2:$B$3000,A11) -> 17 | N11: =COUNTIFS(Quests!$B$2:$B$3000,A11,Quests!$I$2:$I$3000,"Open") -> 10 | O11: =SUMPRODUCT(--(COUNTIFS(Quests!$B$2:$B$3000,A11,Quests!$I$2:$I$3000,"Open",Quests!$E$2:$E$3000,{"Leader";"Planner";"Expert";"Maker";"Checker";"Storyteller";"Patron";"User"})>0)) -> 8 | P11: =SUMIF(Budget!$A$2:$A$3000,A11,Budget!$C$2:$C$3000) -> 800000 | Q11: Kavya Iyer | R11: Product manager, Bengaluru | S11: Bengaluru, India | T11: New | U11: Bengaluru has roughly 13,000–14,000 km of city-run roads, and potholes come back after every monsoon. People complain on the city's Sahaaya app or the 1533 helpline, but many complaints are closed without a repair, and nobody publishes ward-by-ward fix rates. Two-wheeler riders take most of the risk. | V11: Bengaluru's 1.3 crore or so residents, above all two-wheeler riders, delivery workers, cyclists and pedestrians. The pilot covers 20 wards in the east and south of the city, then expands. | W11: Roads belong to different owners: the city corporation, BDA, NHAI, metro works, and water or power utilities that dig trenches. Each can point at another. Contractors are paid per job, and defect-liability clauses that should force free re-repair are rarely enforced. The complaint system measures closure, not repair, and city governance and ward maps are being reorganised, so it's often unclear which officer is responsible. | X11: • Pothole crashes on mapped roads fall by half • 5,000 unique potholes pinned, each with a photo, GPS, time, size and road owner • At least 95% of verified pins filed through an official channel, each with a complaint ID • 80% of filed potholes show a verified repair (after-photo) within 90 days • A public ward scoreboard showing median days to fix, updated weekly • Zero road-safety incidents among players | Y11: • Never photograph from a moving vehicle or while standing in traffic. Pull over first or skip it. • No faces or number plates in photos. Blur them before uploading. • One pin per pothole. File only through official channels, from your own account. No fake, duplicate or bulk bot complaints. • Publish ward and office numbers, never personal attacks on named engineers or workers. • Non-partisan: no party or candidate branding, and the data is shared equally with anyone who asks. | Z11: • Duplicates: phone GPS drifts 5–20 m between buildings, so two riders pin the same pothole as two. • Road ownership: a pothole inside a metro work zone or over a water-board trench is not the corporation's job, and the complaint bounces. • 'Closed' is not 'fixed'. Proving a repair needs a second visit and an after-photo. • Monsoon patches with cold mix often fail within weeks, so a 'fixed' pothole can reopen before day 90. • Ward boundaries and officer lists are changing under the new city corporations, so pins must be re-mapped when new boundaries are published. | AA11: • Delivery-rider community groups who pin on routes they already ride (Rider Saathi Collective, fictional) • Resident welfare associations in pilot wards (South-East RWA Forum, fictional) • A civic-tech volunteer group to host the map and scoreboard (OpenRaasta Labs, fictional) • A retired road engineer to judge repair quality (Kere Roads Advisory, fictional) | AB11: • Sahaaya grievance app and the 1533 helpline (the city's official complaint channels) • Greater Bengaluru Governance Act 2024 (city corporations and ward committees) • BBMP 198-ward boundary files on open civic data portals, plus newly notified ward maps when published • OpenStreetMap road network for snapping pins to roads • IRC:82 Code of Practice for Maintenance of Bituminous Roads (Indian Roads Congress) • RTI Act 2005 Sec. 6 for road work orders and defect-liability periods • Karnataka Public Procurement portal (KPPP) for road repair tenders | AC11: About 7–9 months. That's 6–8 weeks to map, 3–4 weeks to file, then a 90-day tracking window for the last batch. The slowest step is waiting for repairs: crews prioritise main roads and hold back work in heavy rain.
A12: rti | B12: Society | C12: Every rupee reaches Bihar's schools | D12: Money for toilets, books and teachers is sent, but often never arrives. Follow it to 100 schools and get the gaps fixed. | E12: Stuck | F12: Real-world blockers need people, not just agents | G12: 3 | H12: =COUNTIF(Stages!$A$2:$A$1000,A12) -> 6 | I12: 600000 | J12: ₹ | K12: 55 | L12: =COUNTIF(Squads!$B$2:$B$1000,A12) -> 2 | M12: =COUNTIF(Quests!$B$2:$B$3000,A12) -> 17 | N12: =COUNTIFS(Quests!$B$2:$B$3000,A12,Quests!$I$2:$I$3000,"Open") -> 10 | O12: =SUMPRODUCT(--(COUNTIFS(Quests!$B$2:$B$3000,A12,Quests!$I$2:$I$3000,"Open",Quests!$E$2:$E$3000,{"Leader";"Planner";"Expert";"Maker";"Checker";"Storyteller";"Patron";"User"})>0)) -> 8 | P12: =SUMIF(Budget!$A$2:$A$3000,A12,Budget!$C$2:$C$3000) -> 600000 | Q12: Rajesh Kumar | R12: Retired teacher, Patna | S12: Bihar, India | T12: New | U12: Every year each Bihar government school gets grants under Samagra Shiksha, for example a composite school grant of ₹10,000 to ₹1,00,000 depending on how many children are enrolled. Parents almost never see how much came in or what it bought. Toilets show up as 'functional' on UDISE+ but are locked or broken, and library books are bought on paper but not on the shelf. | V12: Parents, School Management Committee (Vidyalaya Shiksha Samiti) members and teachers at 100 government primary and middle schools in Patna, Gaya, Muzaffarpur and Purnia districts. Roughly 25,000 to 35,000 children study there. | W12: The money flows through block and district offices, so no one at the school level sees the whole picture. RTI replies often come late, appeals take many months, and one parent asking alone is easy to ignore. Comparing paper with reality takes 100 site visits, and nobody is paid to do them. | X12: • 50 schools get what was missing • 100 RTI replies received (or a Commission order for each missing one) • 100 school visits done with a 12-item checklist and timestamped photos • 100 one-page report cards published in Hindi, each with the school's right of reply attached • Every gap above ₹5,000 or one missing facility backed by two documents (RTI reply + visit photo) • Report cards presented at 20 or more School Management Committee meetings | Y12: • Strictly non-partisan. No party names, no politicians, no blame language. Report what the papers say and what we saw. • Public records only. No children's faces or names in photos. No staff personal data beyond name and post as given in the RTI reply. • On-ground visits only in school hours, in pairs, after the head teacher says yes. No entry if refused. Note the refusal and leave. • Each school gets 15 days to answer before its report card is published, and the answer is printed beside our findings. • No bribes and no 'speed money', ever. If someone asks for one, log it and leave. | Z12: • PIOs transfer applications under Sec. 6(3) or reply 'information not held', and every transfer restarts a 5-day clock and a new paper trail. • Replies arrive as scanned cashbooks and PFMS printouts in mixed Hindi and English. Turning them into comparable numbers is slow, careful work. • Second appeals at the State Information Commission can wait months for a hearing, and the hearing is in Patna, far from rural applicants. • Grant heads differ by year and by school category, so 'missing money' is often a coding difference rather than theft. You have to know the Samagra Shiksha norms to tell which. • Head teachers may feel accused. Without their trust, visits get refused. | AA12: • A retired-teachers' association that lends volunteers for appeals and visits (Purana Shikshak Manch, fictional) • A law-college RTI clinic that checks appeal drafts (Patliputra Law Clinic, fictional) • A parents' network active in 20 School Management Committees (Abhibhavak Sangh Bihar, fictional) | AB12: • RTI Act 2005: Sec. 6 (application), Sec. 7(1) (30-day reply), Sec. 7(5) (no fee for BPL), Sec. 19(1) and 19(3) (first and second appeal), Sec. 20 (penalty) • Bihar Right to Information Rules 2006 (₹10 fee by cash, demand draft or postal order) • UDISE+ school-level data (enrolment, toilets, library, teachers) and school report cards • Samagra Shiksha Framework for Implementation (composite school grant norms) and Bihar PAB minutes • PFMS fund-transfer records as supplied in RTI replies • India Post registered post tracking (proof of filing) | AC12: About 12 to 15 months in total. The slowest step is stage 3: 30 days for a reply, 30 to 45 days for a first appeal, then often 4 to 9 months before a second appeal is heard at the Commission.
